<?xml version="1.0" encoding="utf-8"?>
<!--STL Source: https://github.com/sapien-sim/xarm7/tree/master/sapien_xarm7/xarm_urdf/xarm_description/meshes-->
<robot name="xarm7">
  <link name="link_base">
    <inertial>
      <origin rpy="0 0 0" xyz="-0.021131 -0.0016302 0.056488"/>
      <mass value="0.88556"/>
      <inertia ixx="0.0030595" ixy="0.00012259" ixz="-0.00062705" iyy="0.0037783" iyz="0.00027023" izz="0.0020125"/>
    </inertial>
    <visual>
      <geometry>
        <mesh filename="package://xarm7/meshes/visual/link_base.STL"/>
      </geometry>
      <origin rpy="0 0 0" xyz="0 0 0"/>
    </visual>
    <collision>
      <geometry>
        <mesh filename="package://xarm7/meshes/collision/link_base.obj"/>
      </geometry>
      <origin rpy="0 0 0" xyz="0 0 0"/>
    </collision>
  </link>
  <link name="link1">
    <inertial>
      <origin rpy="0 0 0" xyz="-0.0002 0.02905 -0.01233"/>
      <mass value="2.382"/>
      <inertia ixx="0.0056905" ixy="-1.579e-05" ixz="5.125e-06" iyy="0.0049566" iyz="-0.000873378" izz="0.003316654"/>
    </inertial>
    <visual>
      <geometry>
        <mesh filename="package://xarm7/meshes/visual/link1.STL"/>
      </geometry>
      <origin rpy="0 0 0" xyz="0 0 0"/>
    </visual>
    <collision>
      <geometry>
        <mesh filename="package://xarm7/meshes/collision/link1.obj"/>
      </geometry>
      <origin rpy="0 0 0" xyz="0 0 0"/>
    </collision>
  </link>
  <joint name="joint1" type="revolute">
    <origin rpy="0 0 0" xyz="0 0 0.267"/>
    <parent link="link_base"/>
    <child link="link1"/>
    <axis xyz="0 0 1"/>
    <limit effort="50" lower="-6.28318530718" upper="6.28318530718" velocity="3.14"/>
    <dynamics damping="10" friction="1"/>
  </joint>
  <link name="link2">
    <inertial>
      <origin rpy="0 0 0" xyz="0.00022 -0.12856 0.01735"/>
      <mass value="1.869"/>
      <inertia ixx="0.0095989" ixy="1.541e-06" ixz="5.56e-06" iyy="0.00382472" iyz="-0.00317156" izz="0.007565669"/>
    </inertial>
    <visual>
      <geometry>
        <mesh filename="package://xarm7/meshes/visual/link2.STL"/>
      </geometry>
      <origin rpy="0 0 0" xyz="0 0 0"/>
    </visual>
    <collision>
      <geometry>
        <mesh filename="package://xarm7/meshes/collision/link2.obj"/>
      </geometry>
      <origin rpy="0 0 0" xyz="0 0 0"/>
    </collision>
  </link>
  <joint name="joint2" type="revolute">
    <origin rpy="-1.5708 0 0" xyz="0 0 0"/>
    <parent link="link1"/>
    <child link="link2"/>
    <axis xyz="0 0 1"/>
    <limit effort="50" lower="-2.059" upper="2.0944" velocity="3.14"/>
    <dynamics damping="10" friction="1"/>
  </joint>
  <link name="link3">
    <inertial>
      <origin rpy="0 0 0" xyz="0.0466 -0.02463 -0.00768"/>
      <mass value="1.6383"/>
      <inertia ixx="0.00310955" ixy="0.00030837" ixz="-0.00058453" iyy="0.00264483" iyz="0.000338893" izz="0.0026624"/>
    </inertial>
    <visual>
      <geometry>
        <mesh filename="package://xarm7/meshes/visual/link3.STL"/>
      </geometry>
      <origin rpy="0 0 0" xyz="0 0 0"/>
    </visual>
    <collision>
      <geometry>
        <mesh filename="package://xarm7/meshes/collision/link3.obj"/>
      </geometry>
      <origin rpy="0 0 0" xyz="0 0 0"/>
    </collision>
  </link>
  <joint name="joint3" type="revolute">
    <origin rpy="1.5708 0 0" xyz="0 -0.293 0"/>
    <parent link="link2"/>
    <child link="link3"/>
    <axis xyz="0 0 1"/>
    <limit effort="30" lower="-6.28318530718" upper="6.28318530718" velocity="3.14"/>
    <dynamics damping="5" friction="1"/>
  </joint>
  <link name="link4">
    <inertial>
      <origin rpy="0 0 0" xyz="0.07047 -0.11575 0.012"/>
      <mass value="1.7269"/>
      <inertia ixx="0.005889" ixy="0.00137112" ixz="0.00088143" iyy="0.00359703" iyz="-0.001762155" izz="0.00543244"/>
    </inertial>
    <visual>
      <geometry>
        <mesh filename="package://xarm7/meshes/visual/link4.STL"/>
      </geometry>
      <origin rpy="0 0 0" xyz="0 0 0"/>
    </visual>
    <collision>
      <geometry>
        <mesh filename="package://xarm7/meshes/collision/link4.obj"/>
      </geometry>
      <origin rpy="0 0 0" xyz="0 0 0"/>
    </collision>
  </link>
  <joint name="joint4" type="revolute">
    <origin rpy="1.5708 0 0" xyz="0.0525 0 0"/>
    <parent link="link3"/>
    <child link="link4"/>
    <axis xyz="0 0 1"/>
    <limit effort="30" lower="-0.19198" upper="3.927" velocity="3.14"/>
    <dynamics damping="5" friction="1"/>
  </joint>
  <link name="link5">
    <inertial>
      <origin rpy="0 0 0" xyz="-0.00032 0.01604 -0.026"/>
      <mass value="1.3203"/>
      <inertia ixx="0.00534665" ixy="1.5117e-05" ixz="-3.69e-07" iyy="0.0049779" iyz="-0.00022132" izz="0.0013624"/>
    </inertial>
    <visual>
      <geometry>
        <mesh filename="package://xarm7/meshes/visual/link5.STL"/>
      </geometry>
      <origin rpy="0 0 0" xyz="0 0 0"/>
    </visual>
    <collision>
      <geometry>
        <mesh filename="package://xarm7/meshes/collision/link5.obj"/>
      </geometry>
      <origin rpy="0 0 0" xyz="0 0 0"/>
    </collision>
  </link>
  <joint name="joint5" type="revolute">
    <origin rpy="1.5708 0 0" xyz="0.0775 -0.3425 0"/>
    <parent link="link4"/>
    <child link="link5"/>
    <axis xyz="0 0 1"/>
    <limit effort="30" lower="-6.28318530718" upper="6.28318530718" velocity="3.14"/>
    <dynamics damping="5" friction="1"/>
  </joint>
  <link name="link6">
    <inertial>
      <origin rpy="0 0 0" xyz="0.06469 0.03278 0.02141"/>
      <mass value="1.325"/>
      <inertia ixx="0.0014745" ixy="-0.000488" ixz="0.0002953" iyy="0.0019037" iyz="0.00014749" izz="0.0023652"/>
    </inertial>
    <visual>
      <geometry>
        <mesh filename="package://xarm7/meshes/visual/link6.STL"/>
      </geometry>
      <origin rpy="0 0 0" xyz="0 0 0"/>
    </visual>
    <collision>
      <geometry>
        <mesh filename="package://xarm7/meshes/collision/link6.obj"/>
      </geometry>
      <origin rpy="0 0 0" xyz="0 0 0"/>
    </collision>
  </link>
  <joint name="joint6" type="revolute">
    <origin rpy="1.5708 0 0" xyz="0 0 0"/>
    <parent link="link5"/>
    <child link="link6"/>
    <axis xyz="0 0 1"/>
    <limit effort="20" lower="-1.69297" upper="3.14159265359" velocity="3.14"/>
    <dynamics damping="2" friction="1"/>
  </joint>
  <link name="link7">
    <inertial>
      <origin rpy="0 0 0" xyz="0 -0.00677 -0.01098"/>
      <mass value="0.17"/>
      <inertia ixx="9.3e-05" ixy="-0.0" ixz="-0.0" iyy="5.87e-05" iyz="-3.6e-06" izz="0.000132"/>
    </inertial>
    <visual>
      <geometry>
        <mesh filename="package://xarm7/meshes/visual/link7.STL"/>
      </geometry>
      <origin rpy="0 0 0" xyz="0 0 0"/>
    </visual>
    <collision>
      <geometry>
        <mesh filename="package://xarm7/meshes/collision/link7.obj"/>
      </geometry>
      <origin rpy="0 0 0" xyz="0 0 0"/>
    </collision>
  </link>
  <joint name="joint7" type="revolute">
    <origin rpy="-1.5708 0 0" xyz="0.076 0.097 0"/>
    <parent link="link6"/>
    <child link="link7"/>
    <axis xyz="0 0 1"/>
    <limit effort="20" lower="-6.28318530718" upper="6.28318530718" velocity="3.14"/>
    <dynamics damping="2" friction="1"/>
  </joint>
  <link name="link_eef"/>
  <joint name="joint_eef" type="fixed">
    <origin xyz="0 0 0" rpy="0 0 0"/>
    <parent link="link7"/>
    <child link="link_eef"/>
  </joint>

  <!-- Connect LeapHand to xarm7 -->
  <joint name="hand_mount" type="fixed">
    <parent link="link_eef"/>
    <child link="base"/>
    <!-- Position the hand 5cm forward of the end effector, no rotation -->
    <origin xyz="0 0 0.05" rpy="0 0 0"/>
  </joint>

  <link name="base"/>
  <joint name="base_joint" type="fixed">
    <parent link="base"/>
    <child link="palm_lower"/>
    <origin xyz="0 0.038 0.098" rpy="0 -1.57079 0"/>
  </joint>

  <link name="palm_lower">
    <visual>
      <origin xyz="-0.0200 0.02575 -0.0347" rpy="0 0 0"/>
      <geometry>
        <mesh filename="package://xarm7/meshes/visual/palm_lower.obj"/>
      </geometry>
    </visual>
    <collision>     <!-- palm_lower -->
      <origin xyz="-0.009 0.008 -0.011" rpy="0 0 0"/>
      <geometry>
        <box size="0.022 0.026 0.034"/>
      </geometry>
    </collision>
    <collision>
      <origin xyz="-0.009 -0.037 -0.011" rpy="0 0 0"/>
      <geometry>
        <box size="0.022 0.026 0.034"/>
      </geometry>
    </collision>
    <collision>
      <origin xyz="-0.009 -0.082 -0.011" rpy="0 0 0"/>
      <geometry>
        <box size="0.022 0.026 0.034"/>
      </geometry>
    </collision>
    <collision>
      <origin xyz="-0.066 -0.078 -0.0115" rpy="0 0 -0.2967"/>
      <geometry>
        <box size="0.058 0.02 0.046"/>
      </geometry>
    </collision>
    <collision>
      <origin xyz="-0.03 -0.035 -0.003" rpy="0 0 0"/>
      <geometry>
        <box size="0.02 0.12 0.03"/>
      </geometry>
    </collision>
    <collision>
      <origin xyz="-0.032 -0.035 -0.024" rpy="0 0.785 0"/>
      <geometry>
        <box size="0.01 0.12 0.02"/>
      </geometry>
    </collision>
    <collision>
      <origin xyz="-0.048 -0.033 -0.0115" rpy="0 0 0"/>
      <geometry>
        <box size="0.024 0.116 0.046"/>
      </geometry>
    </collision>
    <collision>
      <origin xyz="-0.078 -0.053 -0.0115" rpy="0 0 0"/>
      <geometry>
        <box size="0.044 0.052 0.046"/>
      </geometry>
    </collision>
    <collision>
      <origin xyz="-0.098 -0.009 -0.006" rpy="0 0 0"/>
      <geometry>
        <box size="0.004 0.036 0.034"/>
      </geometry>
    </collision>
    <collision>
      <origin xyz="-0.078 -0.003 0.01" rpy="0 0 0"/>
      <geometry>
        <box size="0.044 0.056 0.004"/>
      </geometry>
    </collision>
    <inertial>
      <origin xyz="0 0 0" rpy="0 0 0"/>
      <mass value="0.237"/>
      <inertia ixx="0.000354094" ixy="-0.000001193" ixz="-0.000002445" iyy="0.000260915" iyz="-0.000002905" izz="0.000529257"/>
    </inertial>
  </link>
  <link name="mcp_joint">
    <visual>
      <origin xyz="0.0084 0.0077 0.01465" rpy="0 0 0"/>
      <geometry>
        <mesh filename="package://xarm7/meshes/visual/mcp_joint.obj"/>
      </geometry>
    </visual>
    <collision>      <!-- mcp_joint -->
      <origin xyz="0 0.018 0.0147" rpy="0 0 0"/>
      <geometry>
        <box size="0.02 0.006 0.034"/>
      </geometry>
    </collision>
    <collision>
      <origin xyz="-0.027 0.042 0.015" rpy="0 0 0"/>
      <geometry>
        <box size="0.028 0.04 0.02"/>
      </geometry>
    </collision>
    <collision>
      <origin xyz="-0.0262 0.02 0.0146" rpy="0 0 0"/>
      <geometry>
        <box size="0.034 0.006 0.02"/>
      </geometry>
    </collision>
    <collision>
      <origin xyz="-0.0295 0.035 0.029" rpy="0 0 0"/>
      <geometry>
        <box size="0.02 0.024 0.008"/>
      </geometry>
    </collision>
    <collision>
      <origin xyz="0 0.005 0.03" rpy="0 0 0"/>
      <geometry>
        <box size="0.014 0.02 0.004"/>
      </geometry>
    </collision>
    <collision>
      <origin xyz="0 0.005 -0.001" rpy="0 0 0"/>
      <geometry>
        <box size="0.014 0.02 0.004"/>
      </geometry>
    </collision>
    <inertial>
      <origin xyz="0 0 0" rpy="0 0 0"/>
      <mass value="0.044"/>
      <inertia ixx="0.000011499" ixy="0.000003049" ixz="0.000000121" iyy="0.000007796" iyz="0.000000112" izz="0.000014759"/>
    </inertial>
  </link>
  <link name="pip">
    <visual>
      <origin xyz="0.0096 0.0002 0.0007" rpy="-1.57079 -1.57079 0"/>
      <geometry>
        <mesh filename="package://xarm7/meshes/visual/pip.obj"/>
      </geometry>
    </visual>
    <collision>     <!-- pip -->
      <origin xyz="0.0075 -0.0002 -0.011" rpy="0 0 0"/>
      <geometry>
        <box size="0.034 0.026 0.022"/>
      </geometry>
    </collision>
    <inertial>
      <origin xyz="0 0 0" rpy="0 0 0"/>
      <mass value="0.032"/>
      <inertia ixx="0.000004798" ixy="0.000000012" ixz="0.000000004" iyy="0.000002862" iyz="0.000000011" izz="0.000004234"/>
    </inertial>
  </link>
  <link name="dip">
    <visual>
      <origin xyz="0.0211 -0.0084 0.0097" rpy="-3.1415926 0 0"/>
      <geometry>
        <mesh filename="package://xarm7/meshes/visual/dip.obj"/>
      </geometry>
    </visual>
    <collision>     <!-- dip -->
      <origin xyz="0 -0.02 0.015" rpy="0 0 0"/>
      <geometry>
        <box size="0.016 0.006 0.026"/>
      </geometry>
    </collision>
    <collision>
      <origin xyz="0 -0.016 0.015" rpy="0 0 0"/>
      <geometry>
        <box size="0.02 0.004 0.034"/>
      </geometry>
    </collision>
    <collision>
      <origin xyz="0 -0.0045 0.03" rpy="0 0 0"/>
      <geometry>
        <box size="0.014 0.02 0.004"/>
      </geometry>
    </collision>
    <collision>
      <origin xyz="0 -0.0045 0" rpy="0 0 0"/>
      <geometry>
        <box size="0.014 0.02 0.004"/>
      </geometry>
    </collision>
    <collision>
      <origin xyz="0.0075 -0.035 0.015" rpy="0 0 0"/>
      <geometry>
        <box size="0.034 0.022 0.026"/>
      </geometry>
    </collision>
    <inertial>
      <origin xyz="0 0 0" rpy="0 0 0"/>
      <mass value="0.037"/>
      <inertia ixx="0.000005542" ixy="-0.000000607" ixz="-0.000000017" iyy="0.000005727" iyz="-0.000000023" izz="0.000006682"/>
    </inertial>
  </link>
  <link name="fingertip">
    <visual>
      <origin xyz="0.0132 -0.0061 0.0144" rpy="3.1415926 0 0"/>
      <geometry>
        <mesh filename="package://xarm7/meshes/visual/fingertip.obj"/>
      </geometry>
    </visual>
    <collision>     <!-- fingertip -->
      <origin xyz="0 -0.017 0.015" rpy="0 0 0"/>
      <geometry>
        <box size="0.02 0.006 0.03"/>
      </geometry>
    </collision>
    <collision>
      <origin xyz="0 -0.006 0.03" rpy="0 0 0"/>
      <geometry>
        <box size="0.014 0.022 0.004"/>
      </geometry>
    </collision>
    <collision>
      <origin xyz="0 -0.006 -0.001" rpy="0 0 0"/>
      <geometry>
        <box size="0.014 0.022 0.004"/>
      </geometry>
    </collision>
    <collision>
      <origin xyz="0 0 0" rpy="0 0 0"/>
      <geometry>
        <mesh filename="package://xarm7/meshes/collision/white_tip.obj"/>
      </geometry>
    </collision>
    <inertial>
      <origin xyz="0 0 0" rpy="0 0 0"/>
      <mass value="0.016"/>
      <inertia ixx="0.000003368" ixy="0.000000115" ixz="0" iyy="0.000001556" iyz="0" izz="0.000002863"/>
    </inertial>
  </link>

  <joint name="0" type="revolute">
    <origin xyz="-0.0122 0.03810 0.01450" rpy="-1.57079 0 1.57079"/>
    <parent link="mcp_joint"/>
    <child link="pip"/>
    <axis xyz="0 0 -1"/>
    <limit effort="0.95" velocity="8.48" lower="-1.047" upper="1.047"/>
    <joint_properties friction="0.0"/>
  </joint>
  <joint name="1" type="revolute">
    <origin xyz="-0.0070 0.0230 -0.0187" rpy="1.57079 1.57079 0"/>
    <parent link="palm_lower"/>
    <child link="mcp_joint"/>
    <axis xyz="0 0 -1"/>
    <limit effort="0.95" velocity="8.48" lower="-0.314" upper="2.23"/>
    <joint_properties friction="0.0"/>
  </joint>
  <joint name="2" type="revolute">
    <origin xyz="0.015 0.0143 -0.013" rpy="1.57079 -1.57079 0"/>
    <parent link="pip"/>
    <child link="dip"/>
    <axis xyz="0 0 -1"/>
    <limit effort="0.95" velocity="8.48" lower="-0.506" upper="1.885"/>
    <joint_properties friction="0.0"/>
  </joint>
  <joint name="3" type="revolute">
    <origin xyz="0 -0.0361 0.0002" rpy="0 0 0"/>
    <parent link="dip"/>
    <child link="fingertip"/>
    <axis xyz="0 0 -1"/>
    <limit effort="0.95" velocity="8.48" lower="-0.366" upper="2.042"/>
    <joint_properties friction="0.0"/>
  </joint>
  <link name="mcp_joint_2">
    <visual>
      <origin xyz="0.0084 0.0077 0.01465" rpy="0 0 0"/>
      <geometry>
        <mesh filename="package://xarm7/meshes/visual/mcp_joint.obj"/>
      </geometry>
    </visual>
    <collision>      <!-- mcp_joint -->
      <origin xyz="0 0.018 0.0147" rpy="0 0 0"/>
      <geometry>
        <box size="0.02 0.006 0.034"/>
      </geometry>
    </collision>
    <collision>
      <origin xyz="-0.027 0.042 0.015" rpy="0 0 0"/>
      <geometry>
        <box size="0.028 0.04 0.02"/>
      </geometry>
    </collision>
    <collision>
      <origin xyz="-0.0262 0.02 0.0146" rpy="0 0 0"/>
      <geometry>
        <box size="0.034 0.006 0.02"/>
      </geometry>
    </collision>
    <collision>
      <origin xyz="-0.0295 0.035 0.029" rpy="0 0 0"/>
      <geometry>
        <box size="0.02 0.024 0.008"/>
      </geometry>
    </collision>
    <collision>
      <origin xyz="0 0.005 0.03" rpy="0 0 0"/>
      <geometry>
        <box size="0.014 0.02 0.004"/>
      </geometry>
    </collision>
    <collision>
      <origin xyz="0 0.005 -0.001" rpy="0 0 0"/>
      <geometry>
        <box size="0.014 0.02 0.004"/>
      </geometry>
    </collision>
    <inertial>
      <origin xyz="0 0 0" rpy="0 0 0"/>
      <mass value="0.044"/>
      <inertia ixx="0.000011499" ixy="0.000003049" ixz="0.000000121" iyy="0.000007796" iyz="0.000000112" izz="0.000014759"/>
    </inertial>
  </link>
  <link name="pip_2">
    <visual>
      <origin xyz="0.0096 0.0003 0.0007" rpy="-1.57079 -1.57079 0"/>
      <geometry>
        <mesh filename="package://xarm7/meshes/visual/pip.obj"/>
      </geometry>
    </visual>
    <collision>     <!-- pip -->
      <origin xyz="0.0075 -0.0002 -0.011" rpy="0 0 0"/>
      <geometry>
        <box size="0.034 0.026 0.022"/>
      </geometry>
    </collision>
    <inertial>
      <origin xyz="0 0 0" rpy="0 0 0"/>
      <mass value="0.032"/>
      <inertia ixx="0.000004798" ixy="0.000000012" ixz="0.000000004" iyy="0.000002862" iyz="0.000000011" izz="0.000004234"/>
    </inertial>
  </link>
  <link name="dip_2">
    <visual>
      <origin xyz="0.0211 -0.0084 0.0097" rpy="-3.14159 0 0"/>
      <geometry>
        <mesh filename="package://xarm7/meshes/visual/dip.obj"/>
      </geometry>
    </visual>
    <collision>     <!-- dip -->
      <origin xyz="0 -0.02 0.015" rpy="0 0 0"/>
      <geometry>
        <box size="0.016 0.006 0.026"/>
      </geometry>
    </collision>
    <collision>
      <origin xyz="0 -0.016 0.015" rpy="0 0 0"/>
      <geometry>
        <box size="0.02 0.004 0.034"/>
      </geometry>
    </collision>
    <collision>
      <origin xyz="0 -0.0045 0.03" rpy="0 0 0"/>
      <geometry>
        <box size="0.014 0.02 0.004"/>
      </geometry>
    </collision>
    <collision>
      <origin xyz="0 -0.0045 0" rpy="0 0 0"/>
      <geometry>
        <box size="0.014 0.02 0.004"/>
      </geometry>
    </collision>
    <collision>
      <origin xyz="0.0075 -0.035 0.015" rpy="0 0 0"/>
      <geometry>
        <box size="0.034 0.022 0.026"/>
      </geometry>
    </collision>
    <inertial>
      <origin xyz="0 0 0" rpy="0 0 0"/>
      <mass value="0.037"/>
      <inertia ixx="0.000005542" ixy="-0.000000607" ixz="-0.000000017" iyy="0.000005727" iyz="-0.000000023" izz="0.000006682"/>
    </inertial>
  </link>
  <link name="fingertip_2">
    <visual>
      <origin xyz="0.0132 -0.0061 0.01450" rpy="3.14159 0 0"/>
      <geometry>
        <mesh filename="package://xarm7/meshes/visual/fingertip.obj"/>
      </geometry>
    </visual>
    <collision>     <!-- fingertip -->
      <origin xyz="0 -0.017 0.015" rpy="0 0 0"/>
      <geometry>
        <box size="0.02 0.006 0.03"/>
      </geometry>
    </collision>
    <collision>
      <origin xyz="0 -0.006 0.03" rpy="0 0 0"/>
      <geometry>
        <box size="0.014 0.022 0.004"/>
      </geometry>
    </collision>
    <collision>
      <origin xyz="0 -0.006 -0.001" rpy="0 0 0"/>
      <geometry>
        <box size="0.014 0.022 0.004"/>
      </geometry>
    </collision>
    <collision>
      <origin xyz="0 0 0" rpy="0 0 0"/>
      <geometry>
        <mesh filename="package://xarm7/meshes/collision/white_tip.obj"/>
      </geometry>
    </collision>
    <inertial>
      <origin xyz="0 0 0" rpy="0 0 0"/>
      <mass value="0.016"/>
      <inertia ixx="0.000003368" ixy="0.000000115" ixz="0" iyy="0.000001556" iyz="0" izz="0.000002863"/>
    </inertial>
  </link>
  <joint name="4" type="revolute">
    <origin xyz="-0.0122 0.0381 0.0145" rpy="-1.57079 0 1.57079"/>
    <parent link="mcp_joint_2"/>
    <child link="pip_2"/>
    <axis xyz="0 0 -1"/>
    <limit effort="0.95" velocity="8.48" lower="-1.047" upper="1.047"/>
    <joint_properties friction="0.0"/>
  </joint>
  <joint name="5" type="revolute">
    <origin xyz="-0.0071 -0.0224 -0.0187" rpy="1.57079 1.57079 0"/>
    <parent link="palm_lower"/>
    <child link="mcp_joint_2"/>
    <axis xyz="0 0 -1"/>
    <limit effort="0.95" velocity="8.48" lower="-0.314" upper="2.23"/>
    <joint_properties friction="0.0"/>
  </joint>
  <joint name="6" type="revolute">
    <origin xyz="0.015 0.0143 -0.013" rpy="1.57079 -1.57079 0"/>
    <parent link="pip_2"/>
    <child link="dip_2"/>
    <axis xyz="0 0 -1"/>
    <limit effort="0.95" velocity="8.48" lower="-0.506" upper="1.885"/>
    <joint_properties friction="0.0"/>
  </joint>
  <joint name="7" type="revolute">
    <origin xyz="0 -0.0361 0.0002" rpy="0 0 0"/>
    <parent link="dip_2"/>
    <child link="fingertip_2"/>
    <axis xyz="0 0 -1"/>
    <limit effort="0.95" velocity="8.48" lower="-0.366" upper="2.042"/>
    <joint_properties friction="0.0"/>
  </joint>
  <link name="mcp_joint_3">
    <visual>
      <origin xyz="0.0084 0.0077 0.01465" rpy="0 0 0"/>
      <geometry>
        <mesh filename="package://xarm7/meshes/visual/mcp_joint.obj"/>
      </geometry>
    </visual>
    <collision>      <!-- mcp_joint -->
      <origin xyz="0 0.018 0.0147" rpy="0 0 0"/>
      <geometry>
        <box size="0.02 0.006 0.034"/>
      </geometry>
    </collision>
    <collision>
      <origin xyz="-0.027 0.042 0.015" rpy="0 0 0"/>
      <geometry>
        <box size="0.028 0.04 0.02"/>
      </geometry>
    </collision>
    <collision>
      <origin xyz="-0.0262 0.02 0.0146" rpy="0 0 0"/>
      <geometry>
        <box size="0.034 0.006 0.02"/>
      </geometry>
    </collision>
    <collision>
      <origin xyz="-0.0295 0.035 0.029" rpy="0 0 0"/>
      <geometry>
        <box size="0.02 0.024 0.008"/>
      </geometry>
    </collision>
    <collision>
      <origin xyz="0 0.005 0.03" rpy="0 0 0"/>
      <geometry>
        <box size="0.014 0.02 0.004"/>
      </geometry>
    </collision>
    <collision>
      <origin xyz="0 0.005 -0.001" rpy="0 0 0"/>
      <geometry>
        <box size="0.014 0.02 0.004"/>
      </geometry>
    </collision>
    <inertial>
      <origin xyz="0 0 0" rpy="0 0 0"/>
      <mass value="0.044"/>
      <inertia ixx="0.000011499" ixy="0.000003049" ixz="0.000000121" iyy="0.000007796" iyz="0.000000112" izz="0.000014759"/>
    </inertial>
  </link>
  <link name="pip_3">
    <visual>
      <origin xyz="0.0096 0.0003 0.0007" rpy="-1.57079 -1.57079 0"/>
      <geometry>
        <mesh filename="package://xarm7/meshes/visual/pip.obj"/>
      </geometry>
    </visual>
    <collision>     <!-- pip -->
      <origin xyz="0.0075 -0.0002 -0.011" rpy="0 0 0"/>
      <geometry>
        <box size="0.034 0.026 0.022"/>
      </geometry>
    </collision>
    <inertial>
      <origin xyz="0 0 0" rpy="0 0 0"/>
      <mass value="0.032"/>
      <inertia ixx="0.000004798" ixy="0.000000012" ixz="0.000000004" iyy="0.000002862" iyz="0.000000011" izz="0.000004234"/>
    </inertial>
  </link>
  <link name="dip_3">
    <visual>
      <origin xyz="0.0211 -0.0084 0.0097" rpy="-3.14159 0 0"/>
      <geometry>
        <mesh filename="package://xarm7/meshes/visual/dip.obj"/>
      </geometry>
    </visual>
    <collision>     <!-- dip -->
      <origin xyz="0 -0.02 0.015" rpy="0 0 0"/>
      <geometry>
        <box size="0.016 0.006 0.026"/>
      </geometry>
    </collision>
    <collision>
      <origin xyz="0 -0.016 0.015" rpy="0 0 0"/>
      <geometry>
        <box size="0.02 0.004 0.034"/>
      </geometry>
    </collision>
    <collision>
      <origin xyz="0 -0.0045 0.03" rpy="0 0 0"/>
      <geometry>
        <box size="0.014 0.02 0.004"/>
      </geometry>
    </collision>
    <collision>
      <origin xyz="0 -0.0045 0" rpy="0 0 0"/>
      <geometry>
        <box size="0.014 0.02 0.004"/>
      </geometry>
    </collision>
    <collision>
      <origin xyz="0.0075 -0.035 0.015" rpy="0 0 0"/>
      <geometry>
        <box size="0.034 0.022 0.026"/>
      </geometry>
    </collision>
    <inertial>
      <origin xyz="0 0 0" rpy="0 0 0"/>
      <mass value="0.037"/>
      <inertia ixx="0.000005542" ixy="-0.000000607" ixz="-0.000000017" iyy="0.000005727" iyz="-0.000000023" izz="0.000006682"/>
    </inertial>
  </link>
  <link name="fingertip_3">
    <visual>
      <origin xyz="0.0132 -0.0061 0.01450" rpy="3.14159 0 0"/>
      <geometry>
        <mesh filename="package://xarm7/meshes/visual/fingertip.obj"/>
      </geometry>
    </visual>
    <collision>     <!-- fingertip -->
      <origin xyz="0 -0.017 0.015" rpy="0 0 0"/>
      <geometry>
        <box size="0.02 0.006 0.03"/>
      </geometry>
    </collision>
    <collision>
      <origin xyz="0 -0.006 0.03" rpy="0 0 0"/>
      <geometry>
        <box size="0.014 0.022 0.004"/>
      </geometry>
    </collision>
    <collision>
      <origin xyz="0 -0.006 -0.001" rpy="0 0 0"/>
      <geometry>
        <box size="0.014 0.022 0.004"/>
      </geometry>
    </collision>
    <collision>
      <origin xyz="0 0 0" rpy="0 0 0"/>
      <geometry>
        <mesh filename="package://xarm7/meshes/collision/white_tip.obj"/>
      </geometry>
    </collision>
    <inertial>
      <origin xyz="0 0 0" rpy="0 0 0"/>
      <mass value="0.016"/>
      <inertia ixx="0.000003368" ixy="0.000000115" ixz="0" iyy="0.000001556" iyz="0" izz="0.000002863"/>
    </inertial>
  </link>
  <joint name="8" type="revolute">
    <origin xyz="-0.0122 0.0381 0.0145" rpy="-1.57079 0 1.57079"/>
    <parent link="mcp_joint_3"/>
    <child link="pip_3"/>
    <axis xyz="0 0 -1"/>
    <limit effort="0.95" velocity="8.48" lower="-1.047" upper="1.047"/>
    <joint_properties friction="0.0"/>
  </joint>
  <joint name="9" type="revolute">
    <origin xyz="-0.00709 -0.0678 -0.0187" rpy="1.57079 1.57079 0"/>
    <parent link="palm_lower"/>
    <child link="mcp_joint_3"/>
    <axis xyz="0 0 -1"/>
    <limit effort="0.95" velocity="8.48" lower="-0.314" upper="2.23"/>
    <joint_properties friction="0.0"/>
  </joint>
  <joint name="10" type="revolute">
    <origin xyz="0.015 0.0143 -0.013" rpy="1.57079 -1.57079 0"/>
    <parent link="pip_3"/>
    <child link="dip_3"/>
    <axis xyz="0 0 -1"/>
    <limit effort="0.95" velocity="8.48" lower="-0.506" upper="1.885"/>
    <joint_properties friction="0.0"/>
  </joint>
  <joint name="11" type="revolute">
    <origin xyz="0 -0.03609 0.0002" rpy="0 0 0"/>
    <parent link="dip_3"/>
    <child link="fingertip_3"/>
    <axis xyz="0 0 -1"/>
    <limit effort="0.95" velocity="8.48" lower="-0.366" upper="2.042"/>
    <joint_properties friction="0.0"/>
  </joint>
  <link name="thumb_temp_base">
    <visual>
      <origin xyz="-0.0053 0.0003 0.00078" rpy="-1.57079 -1.57079 0"/>
      <geometry>
        <mesh filename="package://xarm7/meshes/visual/pip.obj"/>
      </geometry>
    </visual>
    <collision>     <!-- pip -->
      <origin xyz="0.0075 -0.0002 -0.011" rpy="0 0 0"/>
      <geometry>
        <box size="0.034 0.026 0.022"/>
      </geometry>
    </collision>
    <inertial>
      <origin xyz="0 0 0" rpy="0 0 0"/>
      <mass value="0.032"/>
      <inertia ixx="0.000004798" ixy="0.000000012" ixz="0.000000004" iyy="0.000002862" iyz="0.000000011" izz="0.000004234"/>
    </inertial>
  </link>
  <link name="thumb_pip">
    <visual>
      <origin xyz="0.01196 0 -0.0158" rpy="1.57079 0 0"/>
      <geometry>
        <mesh filename="package://xarm7/meshes/visual/thumb_pip.obj"/>
      </geometry>
    </visual>
    <collision>     <!-- thumb_pip -->
      <origin xyz="0 0 -0.0015" rpy="0 0 0"/>
      <geometry>
        <box size="0.018 0.033 0.004"/>
      </geometry>
    </collision>
    <collision>
      <origin xyz="0 -0.015 -0.013" rpy="0 0 0"/>
      <geometry>
        <box size="0.014 0.004 0.02"/>
      </geometry>
    </collision>
    <collision>
      <origin xyz="0 0.015 -0.013" rpy="0 0 0"/>
      <geometry>
        <box size="0.014 0.004 0.02"/>
      </geometry>
    </collision>
    <inertial>
      <origin xyz="0 0 0" rpy="0 0 0"/>
      <mass value="0.003"/>
      <inertia ixx="0.000000593" ixy="0" ixz="0" iyy="0.000000549" iyz="0" izz="0.000000224"/>
    </inertial>
  </link>
  <link name="thumb_dip">
    <visual>
      <origin xyz="0.0439 0.0579 -0.0086" rpy="0 0 0"/>
      <geometry>
        <mesh filename="package://xarm7/meshes/visual/thumb_dip.obj"/>
      </geometry>
    </visual>
    <collision>     <!-- thumb_dip -->
      <origin xyz="0 0.0105 -0.014" rpy="0 0 0"/>
      <geometry>
        <box size="0.02 0.04 0.024"/>
      </geometry>
    </collision>
    <collision>
      <origin xyz="0 0.031 -0.015" rpy="0 0 0"/>
      <geometry>
        <box size="0.02 0.004 0.032"/>
      </geometry>
    </collision>
    <collision>
      <origin xyz="0 0.042 0.001" rpy="0 0 0"/>
      <geometry>
        <box size="0.014 0.02 0.004"/>
      </geometry>
    </collision>
    <collision>
      <origin xyz="0 0.042 -0.029" rpy="0 0 0"/>
      <geometry>
        <box size="0.014 0.02 0.004"/>
      </geometry>
    </collision>
    <collision>
      <origin xyz="-0.0135 0.0175 -0.011656" rpy="0 0 0"/>
      <geometry>
        <box size="0.01 0.024 0.018"/>
      </geometry>
    </collision>
    <inertial>
      <origin xyz="0 0 0" rpy="0 0 0"/>
      <mass value="0.038"/>
      <inertia ixx="0.000008474" ixy="0.000000241" ixz="0.000000026" iyy="0.000003841" iyz="0.000000025" izz="0.000007679"/>
    </inertial>
  </link>
  <link name="thumb_fingertip">
    <visual>
      <origin xyz="0.0625 0.0784 0.0489" rpy="0 0 0"/>
      <geometry>
        <mesh filename="package://xarm7/meshes/visual/thumb_fingertip.obj"/>
      </geometry>
    </visual>
    <collision>     <!-- thumb_fingertip -->
      <origin xyz="0 -0.0085 -0.015" rpy="0 0 0"/>
      <geometry>
        <box size="0.02 0.036 0.024"/>
      </geometry>
    </collision>
    <collision>
      <origin xyz="0 -0.029 -0.014" rpy="0 0 0"/>
      <geometry>
        <box size="0.02 0.004 0.03"/>
      </geometry>
    </collision>
    <collision>
      <origin xyz="0.015 -0.0175 -0.0115" rpy="0 0 0"/>
      <geometry>
        <box size="0.008 0.024 0.018"/>
      </geometry>
    </collision>
    <collision>
      <origin xyz="0 0 0" rpy="0 0 0"/>
      <geometry>
        <mesh filename="package://xarm7/meshes/collision/white_tip_thumb.obj"/>
      </geometry>
    </collision>
    <inertial>
      <origin xyz="0 0 0" rpy="0 0 0"/>
      <mass value="0.049"/>
      <inertia ixx="0.000020372" ixy="-0.000000489" ixz="-0.00000003" iyy="0.000004336" iyz="-0.000000097" izz="0.000019845"/>
    </inertial>
  </link>
  <joint name="12" type="revolute">
    <origin xyz="-0.0693 -0.0012 -0.0216" rpy="0 1.57079 0"/>
    <parent link="palm_lower"/>
    <child link="thumb_temp_base"/>
    <axis xyz="0 0 -1"/>
    <limit effort="0.95" velocity="8.48" lower="-0.349" upper="2.094"/>
    <joint_properties friction="0.0"/>
  </joint>
  <joint name="13" type="revolute">
    <origin xyz="0 0.0143 -0.013" rpy="1.57079 -1.57079 0"/>
    <parent link="thumb_temp_base"/>
    <child link="thumb_pip"/>
    <axis xyz="0 0 -1"/>
    <limit effort="0.95" velocity="8.48" lower="-0.47" upper="2.443"/>
    <joint_properties friction="0.0"/>
  </joint>
  <joint name="14" type="revolute">
    <origin xyz="0 0.0145 -0.017" rpy="-1.57079 0 0"/>
    <parent link="thumb_pip"/>
    <child link="thumb_dip"/>
    <axis xyz="0 0 -1"/>
    <limit effort="0.95" velocity="8.48" lower="-1.20" upper="1.90"/>
    <joint_properties friction="0.0"/>
  </joint>
  <joint name="15" type="revolute">
    <origin xyz="0 0.0466 0.0002" rpy="0 0 3.14159"/>
    <parent link="thumb_dip"/>
    <child link="thumb_fingertip"/>
    <axis xyz="0 0 -1"/>
    <limit effort="0.95" velocity="8.48" lower="-1.34" upper="1.88"/>
    <joint_properties friction="0.0"/>
  </joint>

  <!--  virtual auxiliary link-->
  <link name="thumb_tip_head"/>
  <link name="index_tip_head"/>
  <link name="middle_tip_head"/>
  <link name="ring_tip_head"/>
  <joint name="thumb_tip" type="fixed">
    <parent link="thumb_fingertip"/>
    <child link="thumb_tip_head"/>
    <origin rpy="0 0 0" xyz="0 -0.06 -0.015"/>
  </joint>
  <joint name="index_tip" type="fixed">
    <parent link="fingertip"/>
    <child link="index_tip_head"/>
    <origin rpy="0 0 0" xyz="0 -0.048 0.015"/>
  </joint>
  <joint name="middle_tip" type="fixed">
    <parent link="fingertip_2"/>
    <child link="middle_tip_head"/>
    <origin rpy="0 0 0" xyz="0 -0.048 0.015"/>
  </joint>
  <joint name="ring_tip" type="fixed">
    <parent link="fingertip_3"/>
    <child link="ring_tip_head"/>
    <origin rpy="0 0 0" xyz="0 -0.048 0.015"/>
  </joint>
</robot>
